Workbook
Name Slicer_Cost_type: #N/A
Name Slicer_Resource_Provider: #N/A
Name Slicer_Resource_Provider1: #N/A
Name Slicer_Resource_provider21: #N/A
Name Slicer_Status: #N/A
Name Slicer_Status2: #N/A
Name Slicer_Workstream: #N/A
Name Slicer_Workstream2: #N/A
Name Slicer_Workstream3: #N/A

Sheet Read me
A1: Page Level Info
A2: Pages | B2: Information | C2: Connected to the Dashboard | D2: DO NOT EDIT,DELETE ANY FORMULAS. IF IT IS NEEDED PLEASE INFORM THE DEVELOPER
A3: Resource Static | B3: Static Page to Capture Manpower LE details | C3: No
A4: $Dashboard | B4: Overview of Planned vs Actual monthly and Total views Data is fetched from IT Manpower LE and Other LE tabs - Update these tabs to view the correct information | C4: No
A5: Business Manpower LE | B5: Manpower LE details captured and maintained by business | C5: No
A6: IT Manpower LE | B6: Manpower LE details connected to the Power BI dashboard | C6: Yes
A7: Other LE | B7: Non-Resource details connected to the Power BI dashboard | C7: Yes
A8: Tables | B8: Contains the columns connected to the dropdowns used in the following columns: 1. Workstream - All pages 2. Cost Type - Other LE 3. Rate Concat - Resource Static, Business & IT Manpower LE 4. Variance Reasons - Resource Static, Business & IT Manpower LE | C8: Yes
A12: Updating dropdowns example
A13: As shown in the image below: To find out the source of the dropdowns - Click on the cell > Click on Data > Click on Data Validation, this will navigate to the source column where any editing, addition, deletion needed in the dropdown should be done in the destinaion as shown in image 2 only then it will reflect in the column dropdown

Sheet $ Dashboard
C1: Category | D1: Program LE 2026 | E1: Program YTD Actual 2026 | G1: 46023 | I1: 46054 | K1: 46082 | M1: 46113 | O1: 46143 | Q1: 46174 | S1: 46204 | U1: 46235 | W1: 46266 | Y1: 46296 | AA1: 46327 | AC1: 46357
G2: Plan | H2: Actual | I2: Plan | J2: Actual | K2: Plan | L2: Actual | M2: Plan | N2: Actual | O2: Plan | P2: Actual | Q2: Plan | R2: Actual | S2: Plan | T2: Actual | U2: Plan | V2: Actual | W2: Plan | X2: Actual | Y2: Plan | Z2: Actual | AA2: Plan | AB2: Actual | AC2: Plan | AD2: Actual
C3: Business Resource | D3: =SUMIF($G$2:$AF$2,"Plan",G3:AF3) | E3: =SUMIF($G$2:$AF$2,"Actual",G3:AF3) | G3: =I48 | H3: =J48 | I3: =K48 | J3: =L48 | K3: =M48 | L3: =N48 | M3: =O48 | N3: =P48 | ... AD3: =AF48
C4: IT Resource | D4: =SUMIF($G$2:$AF$2,"Plan",G4:AF4) | E4: =SUMIF($G$2:$AF$2,"Actual",G4:AF4) | G4: =I30 | H4: =J30 | I4: =K30 | J4: =L30 | K4: =M30 | L4: =N30 | M4: =O30 | N4: =P30 | ... AD4: =AF30
C5: Resource Total | D5: =SUMIF($G$2:$AF$2,"Plan",G5:AF5) | E5: =SUMIF($G$2:$AF$2,"Actual",G5:AF5) | G5: =SUM(G3:G4) | H5: =SUM(H3:H4) | I5: =SUM(I3:I4) | J5: =SUM(J3:J4) | K5: =SUM(K3:K4) | L5: =SUM(L3:L4) | M5: =SUM(M3:M4) | N5: =SUM(N3:N4) | ... AD5: =SUM(AD3:AD4) | BO5: 10,95 - it | BP5: 5,87-business | BQ5: =10.95+5.87
C6: Non-Resource | D6: =SUMIF($G$2:$AF$2,"Plan",G6:AF6) | E6: =SUMIF($G$2:$AF$2,"Actual",G6:AF6)/1000000 | G6: =I77 | H6: =J77 | I6: =M77 | J6: =L77 | K6: =M77 | L6: =N77 | M6: =Q77 | N6: =P77 | O6: =Q77 | P6: =R77 | Q6: =U77 | R6: =T77 | S6: =U77 | T6: =V77 | U6: =Y77 | V6: =X77 | W6: =Y77 | X6: =Z77 | Y6: =AC77 | Z6: =AB77 | AA6: =AC77 | AB6: =AD77 | AC6: =AG77 | AD6: =AF77
C7: Total | D7: =D6+D5 | E7: =E6+E5 | G7: =SUM(G3:G6) | H7: =SUM(H3:H6) | I7: =SUM(I3:I6) | J7: =SUM(J3:J6) | K7: =SUM(K3:K6) | L7: =SUM(L3:L6) | M7: =SUM(M3:M6) | N7: =SUM(N3:N6) | ... AD7: =SUM(AD3:AD6)
D10: [2026 - 2027] | G10: [2026] | AH10: [2027]
B11: IT Resource cost by WS/PH | C11: Business/IT | D11: Program LE | E11: Program YTD Actual | G11: LE | H11: Actual | I11: 46023 | K11: 46054 | M11: 46082 | O11: 46113 | Q11: 46143 | S11: 46174 | U11: 46204 | W11: 46235 | Y11: 46266 | AA11: 46296 | AC11: 46327 | AE11: 46357 | AH11: LE | AI11: Actual | AJ11: 46388 | AL11: 46419 | AN11: 46447 | AP11: 46478 | AR11: 46508 | AT11: 46539 | AV11: 46569 | AX11: 46600 | AZ11: 46631 | BB11: 46661 | BD11: 46692 | BF11: 46722 | CD11: GIP | CE11: 46023 | CF11: 46054 | CG11: 46082 | CH11: 46113 | CI11: 46143 | CJ11: 46174 | CK11: 46204 | CL11: 46235 | CM11: 46266 | CN11: 46296 | CO11: 46327 | CP11: 46357 | CQ11: 46388 | CR11: 46419 | CS11: 46447 | CT11: 46478 | CU11: 46508 | CV11: 46539 | CW11: 46569 | CX11: 46600 | CY11: 46631 | CZ11: 46661 | DA11: 46692 | DB11: 46722
I12: Plan | J12: Actual | K12: Plan | L12: Actual | M12: Plan | N12: Actual | O12: Plan | P12: Actual | Q12: Plan | R12: Actual | S12: Plan | T12: Actual | U12: Plan | V12: Actual | W12: Plan | X12: Actual | Y12: Plan | Z12: Actual | AA12: Plan | AB12: Actual | AC12: Plan | AD12: Actual | AE12: Plan | AF12: Actual | AJ12: Plan | AK12: =IF(AJ11<=$B$5,"Actual","") | AL12: Plan | AM12: =IF(AL11<=$B$5,"Actual","") | AN12: Plan | AO12: =IF(AN11<=$B$5,"Actual","") | AP12: Plan | AQ12: =IF(AP11<=$B$5,"Actual","") | AR12: Plan | AS12: =IF(AR11<=$B$5,"Actual","") | AT12: Plan | AU12: =IF(AT11<=$B$5,"Actual","") | AV12: Plan | AW12: =IF(AV11<=$B$5,"Actual","") | AX12: Plan | AY12: =IF(AX11<=$B$5,"Actual","") | AZ12: Plan | BA12: =IF(AZ11<=$B$5,"Actual","") | BB12: Plan | BC12: =IF(BB11<=$B$5,"Actual","") | BD12: Plan | BE12: =IF(BD11<=$B$5,"Actual","") | BF12: Plan | BG12: =IF(BF11<=$B$5,"Actual","")
B13: Program Management | C13: IT | D13: =SUM(G13,AH13) | E13: =SUM(H13,AI13) | G13: =SUMIF($I$12:$AF$12,"Plan",I13:AF13)/1000000 | H13: =SUMIF($I$12:$AF$12,"Actual",I13:AF13)/1000000 | I13: =SUMIF(Table4[Workstream],'$ Dashboard'!B13,Table4[Jan_2026_F]) | J13: =SUMIF(Table4[Workstream],'$ Dashboard'!B13,Table4[Jan_2026_A]) | K13: =SUMIF(Table4[Workstream],'$ Dashboard'!B13,Table4[Feb_2026_F]) | L13: =SUMIF(Table4[Workstream],'$ Dashboard'!B13,Table4[Feb_2026_A]) | M13: =SUMIF(Table4[Workstream],'$ Dashboard'!B13,Table4[Mar_2026_F]) | N13: =SUMIF(Table4[Workstream],'$ Dashboard'!B13,Table4[Mar_2026_A]) | O13: =SUMIF(Table4[Workstream],'$ Dashboard'!B13,Table4[Apr_2026_F]) | P13: =SUMIF(Table4[Workstream],'$ Dashboard'!B13,Table4[Apr_2026_A]) | Q13: =SUMIF(Table4[Workstream],'$ Dashboard'!B13,Table4[May_2026_F]) | R13: =SUMIF(Table4[Workstream],'$ Dashboard'!B13,Table4[May_2026_A]) | S13: =SUMIF(Table4[Workstream],'$ Dashboard'!B13,Table4[Jun_2026_F]) | T13: =SUMIF(Table4[Workstream],'$ Dashboard'!B13,Table4[Jun_2026_A]) | U13: =SUMIF(Table4[Workstream],'$ Dashboard'!B13,Table4[Jul_2026_F]) | V13: =SUMIF(Table4[Workstream],'$ Dashboard'!B13,Table4[Jul_2026_A]) | W13: =SUMIF(Table4[Workstream],'$ Dashboard'!B13,Table4[Aug_2026_F]) | X13: =SUMIF(Table4[Workstream],'$ Dashboard'!B13,Table4[Aug_2026_A]) | Y13: =SUMIF(Table4[Workstream],'$ Dashboard'!B13,Table4[Sep_2026_F]) | Z13: =SUMIF(Table4[Workstream],'$ Dashboard'!B13,Table4[Sep_2026_A]) | AA13: =SUMIF(Table4[Workstream],'$ Dashboard'!B13,Table4[Oct_2026_F]) | AB13: =SUMIF(Table4[Workstream],'$ Dashboard'!B13,Table4[Oct_2026_A]) | AC13: =SUMIF(Table4[Workstream],'$ Dashboard'!B13,Table4[Nov_2026_F]) | AD13: =SUMIF(Table4[Workstream],'$ Dashboard'!B13,Table4[Nov_2026_A]) | AE13: =SUMIF(Table4[Workstream],'$ Dashboard'!B13,Table4[Dec_2026_F]) | AF13: =SUMIF(Table4[Workstream],'$ Dashboard'!B13,Table4[Dec_2026_A])+SUMIF(Table46[Workstream],'$ Dashboard'!B13,Table46[Dec_26_A]) | AH13: =SUM(AW13:BG13)/1000000 | AI13: =SUMIF($AJ$12:$BG$12,"Actual",AJ13:BG13)/1000000 | CD13: =SUM(CE13:DB13)/1000000
B14: Prosmar Crude | C14: IT | D14: =SUM(G14,AH14) | E14: =SUM(H14,AI14) | G14: =SUMIF($I$12:$AF$12,"Plan",I14:AF14)/1000000 | H14: =SUMIF($I$12:$AF$12,"Actual",I14:AF14)/1000000 | I14: =SUMIF(Table4[Workstream],'$ Dashboard'!B14,Table4[Jan_2026_F]) | J14: =SUMIF(Table4[Workstream],'$ Dashboard'!B14,Table4[Jan_2026_A]) | K14: =SUMIF(Table4[Workstream],'$ Dashboard'!B14,Table4[Feb_2026_F]) | L14: =SUMIF(Table4[Workstream],'$ Dashboard'!B14,Table4[Feb_2026_A]) | M14: =SUMIF(Table4[Workstream],'$ Dashboard'!B14,Table4[Mar_2026_F]) | N14: =SUMIF(Table4[Workstream],'$ Dashboard'!B14,Table4[Mar_2026_A]) | O14: =SUMIF(Table4[Workstream],'$ Dashboard'!B14,Table4[Apr_2026_F]) | P14: =SUMIF(Table4[Workstream],'$ Dashboard'!B14,Table4[Apr_2026_A]) | Q14: =SUMIF(Table4[Workstream],'$ Dashboard'!B14,Table4[May_2026_F]) | R14: =SUMIF(Table4[Workstream],'$ Dashboard'!B14,Table4[May_2026_A]) | S14: =SUMIF(Table4[Workstream],'$ Dashboard'!B14,Table4[Jun_2026_F]) | T14: =SUMIF(Table4[Workstream],'$ Dashboard'!B14,Table4[Jun_2026_A]) | U14: =SUMIF(Table4[Workstream],'$ Dashboard'!B14,Table4[Jul_2026_F]) | V14: =SUMIF(Table4[Workstream],'$ Dashboard'!B14,Table4[Jul_2026_A]) | W14: =SUMIF(Table4[Workstream],'$ Dashboard'!B14,Table4[Aug_2026_F]) | X14: =SUMIF(Table4[Workstream],'$ Dashboard'!B14,Table4[Aug_2026_A]) | Y14: =SUMIF(Table4[Workstream],'$ Dashboard'!B14,Table4[Sep_2026_F]) | Z14: =SUMIF(Table4[Workstream],'$ Dashboard'!B14,Table4[Sep_2026_A]) | AA14: =SUMIF(Table4[Workstream],'$ Dashboard'!B14,Table4[Oct_2026_F]) | AB14: =SUMIF(Table4[Workstream],'$ Dashboard'!B14,Table4[Oct_2026_A]) | AC14: =SUMIF(Table4[Workstream],'$ Dashboard'!B14,Table4[Nov_2026_F]) | AD14: =SUMIF(Table4[Workstream],'$ Dashboard'!B14,Table4[Nov_2026_A]) | AE14: =SUMIF(Table4[Workstream],'$ Dashboard'!B14,Table4[Dec_2026_F]) | AF14: =SUMIF(Table4[Workstream],'$ Dashboard'!B14,Table4[Dec_2026_A])+SUMIF(Table46[Workstream],'$ Dashboard'!B14,Table46[Dec_26_A]) | AH14: =SUM(AW14:BG14)/1000000 | AI14: =SUMIF($AJ$12:$BG$12,"Actual",AJ14:BG14)/1000000 | CD14: =SUM(CE14:DB14)/1000000
B15: Prosmar Products | C15: IT | D15: =SUM(G15,AH15) | E15: =SUM(H15,AI15) | G15: =SUMIF($I$12:$AF$12,"Plan",I15:AF15)/1000000 | H15: =SUMIF($I$12:$AF$12,"Actual",I15:AF15)/1000000 | I15: =SUMIF(Table4[Workstream],'$ Dashboard'!B15,Table4[Jan_2026_F]) | J15: =SUMIF(Table4[Workstream],'$ Dashboard'!B15,Table4[Jan_2026_A]) | K15: =SUMIF(Table4[Workstream],'$ Dashboard'!B15,Table4[Feb_2026_F]) | L15: =SUMIF(Table4[Workstream],'$ Dashboard'!B15,Table4[Feb_2026_A]) | M15: =SUMIF(Table4[Workstream],'$ Dashboard'!B15,Table4[Mar_2026_F]) | N15: =SUMIF(Table4[Workstream],'$ Dashboard'!B15,Table4[Mar_2026_A]) | O15: =SUMIF(Table4[Workstream],'$ Dashboard'!B15,Table4[Apr_2026_F]) | P15: =SUMIF(Table4[Workstream],'$ Dashboard'!B15,Table4[Apr_2026_A]) | Q15: =SUMIF(Table4[Workstream],'$ Dashboard'!B15,Table4[May_2026_F]) | R15: =SUMIF(Table4[Workstream],'$ Dashboard'!B15,Table4[May_2026_A]) | S15: =SUMIF(Table4[Workstream],'$ Dashboard'!B15,Table4[Jun_2026_F]) | T15: =SUMIF(Table4[Workstream],'$ Dashboard'!B15,Table4[Jun_2026_A]) | U15: =SUMIF(Table4[Workstream],'$ Dashboard'!B15,Table4[Jul_2026_F]) | V15: =SUMIF(Table4[Workstream],'$ Dashboard'!B15,Table4[Jul_2026_A]) | W15: =SUMIF(Table4[Workstream],'$ Dashboard'!B15,Table4[Aug_2026_F]) | X15: =SUMIF(Table4[Workstream],'$ Dashboard'!B15,Table4[Aug_2026_A]) | Y15: =SUMIF(Table4[Workstream],'$ Dashboard'!B15,Table4[Sep_2026_F]) | Z15: =SUMIF(Table4[Workstream],'$ Dashboard'!B15,Table4[Sep_2026_A]) | AA15: =SUMIF(Table4[Workstream],'$ Dashboard'!B15,Table4[Oct_2026_F]) | AB15: =SUMIF(Table4[Workstream],'$ Dashboard'!B15,Table4[Oct_2026_A]) | AC15: =SUMIF(Table4[Workstream],'$ Dashboard'!B15,Table4[Nov_2026_F]) | AD15: =SUMIF(Table4[Workstream],'$ Dashboard'!B15,Table4[Nov_2026_A]) | AE15: =SUMIF(Table4[Workstream],'$ Dashboard'!B15,Table4[Dec_2026_F]) | AF15: =SUMIF(Table4[Workstream],'$ Dashboard'!B15,Table4[Dec_2026_A])+SUMIF(Table46[Workstream],'$ Dashboard'!B15,Table46[Dec_26_A]) | AH15: =SUM(AW15:BG15)/1000000 | AI15: =SUMIF($AJ$12:$BG$12,"Actual",AJ15:BG15)/1000000 | CD15: =SUM(CE15:DB15)/1000000
B16: VPD | C16: IT | D16: =SUM(G16,AH16) | E16: =SUM(H16,AI16) | G16: =SUMIF($I$12:$AF$12,"Plan",I16:AF16)/1000000 | H16: =SUMIF($I$12:$AF$12,"Actual",I16:AF16)/1000000 | I16: =SUMIF(Table4[Workstream],'$ Dashboard'!B16,Table4[Jan_2026_F]) | J16: =SUMIF(Table4[Workstream],'$ Dashboard'!B16,Table4[Jan_2026_A]) | K16: =SUMIF(Table4[Workstream],'$ Dashboard'!B16,Table4[Feb_2026_F]) | L16: =SUMIF(Table4[Workstream],'$ Dashboard'!B16,Table4[Feb_2026_A]) | M16: =SUMIF(Table4[Workstream],'$ Dashboard'!B16,Table4[Mar_2026_F]) | N16: =SUMIF(Table4[Workstream],'$ Dashboard'!B16,Table4[Mar_2026_A]) | O16: =SUMIF(Table4[Workstream],'$ Dashboard'!B16,Table4[Apr_2026_F]) | P16: =SUMIF(Table4[Workstream],'$ Dashboard'!B16,Table4[Apr_2026_A]) | Q16: =SUMIF(Table4[Workstream],'$ Dashboard'!B16,Table4[May_2026_F]) | R16: =SUMIF(Table4[Workstream],'$ Dashboard'!B16,Table4[May_2026_A]) | S16: =SUMIF(Table4[Workstream],'$ Dashboard'!B16,Table4[Jun_2026_F]) | T16: =SUMIF(Table4[Workstream],'$ Dashboard'!B16,Table4[Jun_2026_A]) | U16: =SUMIF(Table4[Workstream],'$ Dashboard'!B16,Table4[Jul_2026_F]) | V16: =SUMIF(Table4[Workstream],'$ Dashboard'!B16,Table4[Jul_2026_A]) | W16: =SUMIF(Table4[Workstream],'$ Dashboard'!B16,Table4[Aug_2026_F]) | X16: =SUMIF(Table4[Workstream],'$ Dashboard'!B16,Table4[Aug_2026_A]) | Y16: =SUMIF(Table4[Workstream],'$ Dashboard'!B16,Table4[Sep_2026_F]) | Z16: =SUMIF(Table4[Workstream],'$ Dashboard'!B16,Table4[Sep_2026_A]) | AA16: =SUMIF(Table4[Workstream],'$ Dashboard'!B16,Table4[Oct_2026_F]) | AB16: =SUMIF(Table4[Workstream],'$ Dashboard'!B16,Table4[Oct_2026_A]) | AC16: =SUMIF(Table4[Workstream],'$ Dashboard'!B16,Table4[Nov_2026_F]) | AD16: =SUMIF(Table4[Workstream],'$ Dashboard'!B16,Table4[Nov_2026_A]) | AE16: =SUMIF(Table4[Workstream],'$ Dashboard'!B16,Table4[Dec_2026_F]) | AF16: =SUMIF(Table4[Workstream],'$ Dashboard'!B16,Table4[Dec_2026_A])+SUMIF(Table46[Workstream],'$ Dashboard'!B16,Table46[Dec_26_A]) | AH16: =SUM(AW16:BG16)/1000000 | AI16: =SUMIF($AJ$12:$BG$12,"Actual",AJ16:BG16)/1000000 | CD16: =SUM(CE16:DB16)/1000000
B17: GATOR | C17: IT | D17: =SUM(G17,AH17) | E17: =SUM(H17,AI17) | G17: =SUMIF($I$12:$AF$12,"Plan",I17:AF17)/1000000 | H17: =SUMIF($I$12:$AF$12,"Actual",I17:AF17)/1000000 | I17: =SUMIF(Table4[Workstream],'$ Dashboard'!B17,Table4[Jan_2026_F]) | J17: =SUMIF(Table4[Workstream],'$ Dashboard'!B17,Table4[Jan_2026_A]) | K17: =SUMIF(Table4[Workstream],'$ Dashboard'!B17,Table4[Feb_2026_F]) | L17: =SUMIF(Table4[Workstream],'$ Dashboard'!B17,Table4[Feb_2026_A]) | M17: =SUMIF(Table4[Workstream],'$ Dashboard'!B17,Table4[Mar_2026_F]) | N17: =SUMIF(Table4[Workstream],'$ Dashboard'!B17,Table4[Mar_2026_A]) | O17: =SUMIF(Table4[Workstream],'$ Dashboard'!B17,Table4[Apr_2026_F]) | P17: =SUMIF(Table4[Workstream],'$ Dashboard'!B17,Table4[Apr_2026_A]) | Q17: =SUMIF(Table4[Workstream],'$ Dashboard'!B17,Table4[May_2026_F]) | R17: =SUMIF(Table4[Workstream],'$ Dashboard'!B17,Table4[May_2026_A]) | S17: =SUMIF(Table4[Workstream],'$ Dashboard'!B17,Table4[Jun_2026_F]) | T17: =SUMIF(Table4[Workstream],'$ Dashboard'!B17,Table4[Jun_2026_A]) | U17: =SUMIF(Table4[Workstream],'$ Dashboard'!B17,Table4[Jul_2026_F]) | V17: =SUMIF(Table4[Workstream],'$ Dashboard'!B17,Table4[Jul_2026_A]) | W17: =SUMIF(Table4[Workstream],'$ Dashboard'!B17,Table4[Aug_2026_F]) | X17: =SUMIF(Table4[Workstream],'$ Dashboard'!B17,Table4[Aug_2026_A]) | Y17: =SUMIF(Table4[Workstream],'$ Dashboard'!B17,Table4[Sep_2026_F]) | Z17: =SUMIF(Table4[Workstream],'$ Dashboard'!B17,Table4[Sep_2026_A]) | AA17: =SUMIF(Table4[Workstream],'$ Dashboard'!B17,Table4[Oct_2026_F]) | AB17: =SUMIF(Table4[Workstream],'$ Dashboard'!B17,Table4[Oct_2026_A]) | AC17: =SUMIF(Table4[Workstream],'$ Dashboard'!B17,Table4[Nov_2026_F]) | AD17: =SUMIF(Table4[Workstream],'$ Dashboard'!B17,Table4[Nov_2026_A]) | AE17: =SUMIF(Table4[Workstream],'$ Dashboard'!B17,Table4[Dec_2026_F]) | AF17: =SUMIF(Table4[Workstream],'$ Dashboard'!B17,Table4[Dec_2026_A])+SUMIF(Table46[Workstream],'$ Dashboard'!B17,Table46[Dec_26_A]) | AH17: =SUM(AW17:BG17)/1000000 | AI17: =SUMIF($AJ$12:$BG$12,"Actual",AJ17:BG17)/1000000 | CD17: =SUM(CE17:DB17)/1000000
B18: USDF | C18: IT | D18: =SUM(G18,AH18) | E18: =SUM(H18,AI18) | G18: =SUMIF($I$12:$AF$12,"Plan",I18:AF18)/1000000 | H18: =SUMIF($I$12:$AF$12,"Actual",I18:AF18)/1000000 | I18: =SUMIF(Table4[Workstream],'$ Dashboard'!B18,Table4[Jan_2026_F]) | J18: =SUMIF(Table4[Workstream],'$ Dashboard'!B18,Table4[Jan_2026_A]) | K18: =SUMIF(Table4[Workstream],'$ Dashboard'!B18,Table4[Feb_2026_F]) | L18: =SUMIF(Table4[Workstream],'$ Dashboard'!B18,Table4[Feb_2026_A]) | M18: =SUMIF(Table4[Workstream],'$ Dashboard'!B18,Table4[Mar_2026_F]) | N18: =SUMIF(Table4[Workstream],'$ Dashboard'!B18,Table4[Mar_2026_A]) | O18: =SUMIF(Table4[Workstream],'$ Dashboard'!B18,Table4[Apr_2026_F]) | P18: =SUMIF(Table4[Workstream],'$ Dashboard'!B18,Table4[Apr_2026_A]) | Q18: =SUMIF(Table4[Workstream],'$ Dashboard'!B18,Table4[May_2026_F]) | R18: =SUMIF(Table4[Workstream],'$ Dashboard'!B18,Table4[May_2026_A]) | S18: =SUMIF(Table4[Workstream],'$ Dashboard'!B18,Table4[Jun_2026_F]) | T18: =SUMIF(Table4[Workstream],'$ Dashboard'!B18,Table4[Jun_2026_A]) | U18: =SUMIF(Table4[Workstream],'$ Dashboard'!B18,Table4[Jul_2026_F]) | V18: =SUMIF(Table4[Workstream],'$ Dashboard'!B18,Table4[Jul_2026_A]) | W18: =SUMIF(Table4[Workstream],'$ Dashboard'!B18,Table4[Aug_2026_F]) | X18: =SUMIF(Table4[Workstream],'$ Dashboard'!B18,Table4[Aug_2026_A]) | Y18: =SUMIF(Table4[Workstream],'$ Dashboard'!B18,Table4[Sep_2026_F]) | Z18: =SUMIF(Table4[Workstream],'$ Dashboard'!B18,Table4[Sep_2026_A]) | AA18: =SUMIF(Table4[Workstream],'$ Dashboard'!B18,Table4[Oct_2026_F]) | AB18: =SUMIF(Table4[Workstream],'$ Dashboard'!B18,Table4[Oct_2026_A]) | AC18: =SUMIF(Table4[Workstream],'$ Dashboard'!B18,Table4[Nov_2026_F]) | AD18: =SUMIF(Table4[Workstream],'$ Dashboard'!B18,Table4[Nov_2026_A]) | AE18: =SUMIF(Table4[Workstream],'$ Dashboard'!B18,Table4[Dec_2026_F]) | AF18: =SUMIF(Table4[Workstream],'$ Dashboard'!B18,Table4[Dec_2026_A])+SUMIF(Table46[Workstream],'$ Dashboard'!B18,Table46[Dec_26_A]) | AH18: =SUM(AW18:BG18)/1000000 | AI18: =SUMIF($AJ$12:$BG$12,"Actual",AJ18:BG18)/1000000 | CD18: =SUM(CE18:DB18)/1000000
B19: JIGSAW & PDS Process work | C19: IT | D19: =SUM(G19,AH19) | E19: =SUM(H19,AI19) | G19: =SUMIF($I$12:$AF$12,"Plan",I19:AF19)/1000000 | H19: =SUMIF($I$12:$AF$12,"Actual",I19:AF19)/1000000 | I19: =SUMIF(Table4[Workstream],'$ Dashboard'!B19,Table4[Jan_2026_F]) | J19: =SUMIF(Table4[Workstream],'$ Dashboard'!B19,Table4[Jan_2026_A]) | K19: =SUMIF(Table4[Workstream],'$ Dashboard'!B19,Table4[Feb_2026_F]) | L19: =SUMIF(Table4[Workstream],'$ Dashboard'!B19,Table4[Feb_2026_A]) | M19: =SUMIF(Table4[Workstream],'$ Dashboard'!B19,Table4[Mar_2026_F]) | N19: =SUMIF(Table4[Workstream],'$ Dashboard'!B19,Table4[Mar_2026_A]) | O19: =SUMIF(Table4[Workstream],'$ Dashboard'!B19,Table4[Apr_2026_F]) | P19: =SUMIF(Table4[Workstream],'$ Dashboard'!B19,Table4[Apr_2026_A]) | Q19: =SUMIF(Table4[Workstream],'$ Dashboard'!B19,Table4[May_2026_F]) | R19: =SUMIF(Table4[Workstream],'$ Dashboard'!B19,Table4[May_2026_A]) | S19: =SUMIF(Table4[Workstream],'$ Dashboard'!B19,Table4[Jun_2026_F]) | T19: =SUMIF(Table4[Workstream],'$ Dashboard'!B19,Table4[Jun_2026_A]) | U19: =SUMIF(Table4[Workstream],'$ Dashboard'!B19,Table4[Jul_2026_F]) | V19: =SUMIF(Table4[Workstream],'$ Dashboard'!B19,Table4[Jul_2026_A]) | W19: =SUMIF(Table4[Workstream],'$ Dashboard'!B19,Table4[Aug_2026_F]) | X19: =SUMIF(Table4[Workstream],'$ Dashboard'!B19,Table4[Aug_2026_A]) | Y19: =SUMIF(Table4[Workstream],'$ Dashboard'!B19,Table4[Sep_2026_F]) | Z19: =SUMIF(Table4[Workstream],'$ Dashboard'!B19,Table4[Sep_2026_A]) | AA19: =SUMIF(Table4[Workstream],'$ Dashboard'!B19,Table4[Oct_2026_F]) | AB19: =SUMIF(Table4[Workstream],'$ Dashboard'!B19,Table4[Oct_2026_A]) | AC19: =SUMIF(Table4[Workstream],'$ Dashboard'!B19,Table4[Nov_2026_F]) | AD19: =SUMIF(Table4[Workstream],'$ Dashboard'!B19,Table4[Nov_2026_A]) | AE19: =SUMIF(Table4[Workstream],'$ Dashboard'!B19,Table4[Dec_2026_F]) | AF19: =SUMIF(Table4[Workstream],'$ Dashboard'!B19,Table4[Dec_2026_A])+SUMIF(Table46[Workstream],'$ Dashboard'!B19,Table46[Dec_26_A]) | AH19: =SUM(AW19:BG19)/1000000 | AI19: =SUMIF($AJ$12:$BG$12,"Actual",AJ19:BG19)/1000000 | CD19: =SUM(CE19:DB19)/1000000
B20: DA Desk | C20: IT | D20: =SUM(G20,AH20) | E20: =SUM(H20,AI20) | G20: =SUMIF($I$12:$AF$12,"Plan",I20:AF20)/1000000 | H20: =SUMIF($I$12:$AF$12,"Actual",I20:AF20)/1000000 | I20: =SUMIF(Table4[Workstream],'$ Dashboard'!B20,Table4[Jan_2026_F]) | J20: =SUMIF(Table4[Workstream],'$ Dashboard'!B20,Table4[Jan_2026_A]) | K20: =SUMIF(Table4[Workstream],'$ Dashboard'!B20,Table4[Feb_2026_F]) | L20: =SUMIF(Table4[Workstream],'$ Dashboard'!B20,Table4[Feb_2026_A]) | M20: =SUMIF(Table4[Workstream],'$ Dashboard'!B20,Table4[Mar_2026_F]) | N20: =SUMIF(Table4[Workstream],'$ Dashboard'!B20,Table4[Mar_2026_A]) | O20: =SUMIF(Table4[Workstream],'$ Dashboard'!B20,Table4[Apr_2026_F]) | P20: =SUMIF(Table4[Workstream],'$ Dashboard'!B20,Table4[Apr_2026_A]) | Q20: =SUMIF(Table4[Workstream],'$ Dashboard'!B20,Table4[May_2026_F]) | R20: =SUMIF(Table4[Workstream],'$ Dashboard'!B20,Table4[May_2026_A]) | S20: =SUMIF(Table4[Workstream],'$ Dashboard'!B20,Table4[Jun_2026_F]) | T20: =SUMIF(Table4[Workstream],'$ Dashboard'!B20,Table4[Jun_2026_A]) | U20: =SUMIF(Table4[Workstream],'$ Dashboard'!B20,Table4[Jul_2026_F]) | V20: =SUMIF(Table4[Workstream],'$ Dashboard'!B20,Table4[Jul_2026_A]) | W20: =SUMIF(Table4[Workstream],'$ Dashboard'!B20,Table4[Aug_2026_F]) | X20: =SUMIF(Table4[Workstream],'$ Dashboard'!B20,Table4[Aug_2026_A]) | Y20: =SUMIF(Table4[Workstream],'$ Dashboard'!B20,Table4[Sep_2026_F]) | Z20: =SUMIF(Table4[Workstream],'$ Dashboard'!B20,Table4[Sep_2026_A]) | AA20: =SUMIF(Table4[Workstream],'$ Dashboard'!B20,Table4[Oct_2026_F]) | AB20: =SUMIF(Table4[Workstream],'$ Dashboard'!B20,Table4[Oct_2026_A]) | AC20: =SUMIF(Table4[Workstream],'$ Dashboard'!B20,Table4[Nov_2026_F]) | AD20: =SUMIF(Table4[Workstream],'$ Dashboard'!B20,Table4[Nov_2026_A]) | AE20: =SUMIF(Table4[Workstream],'$ Dashboard'!B20,Table4[Dec_2026_F]) | AF20: =SUMIF(Table4[Workstream],'$ Dashboard'!B20,Table4[Dec_2026_A])+SUMIF(Table46[Workstream],'$ Dashboard'!B20,Table46[Dec_26_A]) | AH20: =SUM(AW20:BG20)/1000000 | AI20: =SUMIF($AJ$12:$BG$12,"Actual",AJ20:BG20)/1000000 | CD20: =SUM(CE20:DB20)/1000000
B21: IDT | C21: IT | D21: =SUM(G21,AH21) | E21: =SUM(H21,AI21) | G21: =SUMIF($I$12:$AF$12,"Plan",I21:AF21)/1000000 | H21: =SUMIF($I$12:$AF$12,"Actual",I21:AF21)/1000000 | I21: =SUMIF(Table4[Workstream],'$ Dashboard'!B21,Table4[Jan_2026_F]) | J21: =SUMIF(Table4[Workstream],'$ Dashboard'!B21,Table4[Jan_2026_A]) | K21: =SUMIF(Table4[Workstream],'$ Dashboard'!B21,Table4[Feb_2026_F]) | L21: =SUMIF(Table4[Workstream],'$ Dashboard'!B21,Table4[Feb_2026_A]) | M21: =SUMIF(Table4[Workstream],'$ Dashboard'!B21,Table4[Mar_2026_F]) | N21: =SUMIF(Table4[Workstream],'$ Dashboard'!B21,Table4[Mar_2026_A]) | O21: =SUMIF(Table4[Workstream],'$ Dashboard'!B21,Table4[Apr_2026_F]) | P21: =SUMIF(Table4[Workstream],'$ Dashboard'!B21,Table4[Apr_2026_A]) | Q21: =SUMIF(Table4[Workstream],'$ Dashboard'!B21,Table4[May_2026_F]) | R21: =SUMIF(Table4[Workstream],'$ Dashboard'!B21,Table4[May_2026_A]) | S21: =SUMIF(Table4[Workstream],'$ Dashboard'!B21,Table4[Jun_2026_F]) | T21: =SUMIF(Table4[Workstream],'$ Dashboard'!B21,Table4[Jun_2026_A]) | U21: =SUMIF(Table4[Workstream],'$ Dashboard'!B21,Table4[Jul_2026_F]) | V21: =SUMIF(Table4[Workstream],'$ Dashboard'!B21,Table4[Jul_2026_A]) | W21: =SUMIF(Table4[Workstream],'$ Dashboard'!B21,Table4[Aug_2026_F]) | X21: =SUMIF(Table4[Workstream],'$ Dashboard'!B21,Table4[Aug_2026_A]) | Y21: =SUMIF(Table4[Workstream],'$ Dashboard'!B21,Table4[Sep_2026_F]) | Z21: =SUMIF(Table4[Workstream],'$ Dashboard'!B21,Table4[Sep_2026_A]) | AA21: =SUMIF(Table4[Workstream],'$ Dashboard'!B21,Table4[Oct_2026_F]) | AB21: =SUMIF(Table4[Workstream],'$ Dashboard'!B21,Table4[Oct_2026_A]) | AC21: =SUMIF(Table4[Workstream],'$ Dashboard'!B21,Table4[Nov_2026_F]) | AD21: =SUMIF(Table4[Workstream],'$ Dashboard'!B21,Table4[Nov_2026_A]) | AE21: =SUMIF(Table4[Workstream],'$ Dashboard'!B21,Table4[Dec_2026_F]) | AF21: =SUMIF(Table4[Workstream],'$ Dashboard'!B21,Table4[Dec_2026_A])+SUMIF(Table46[Workstream],'$ Dashboard'!B21,Table46[Dec_26_A]) | AH21: =SUM(AW21:BG21)/1000000 | AI21: =SUMIF($AJ$12:$BG$12,"Actual",AJ21:BG21)/1000000 | CD21: =SUM(CE21:DB21)/1000000
D22: =SUM(G22,AH22) | E22: =SUM(H22,AI22) | G22: =SUMIF($I$12:$AF$12,"Plan",I22:AF22)/1000000 | H22: =SUMIF($I$12:$AF$12,"Actual",I22:AF22)/1000000 | I22: =SUMIF(Table4[Workstream],'$ Dashboard'!B22,Table4[Jan_2026_F]) | J22: =SUMIF(Table4[Workstream],'$ Dashboard'!B22,Table4[Jan_2026_A]) | K22: =SUMIF(Table4[Workstream],'$ Dashboard'!B22,Table4[Feb_2026_F]) | L22: =SUMIF(Table4[Workstream],'$ Dashboard'!B22,Table4[Feb_2026_A]) | M22: =SUMIF(Table4[Workstream],'$ Dashboard'!B22,Table4[Mar_2026_F]) | N22: =SUMIF(Table4[Workstream],'$ Dashboard'!B22,Table4[Mar_2026_A]) | O22: =SUMIF(Table4[Workstream],'$ Dashboard'!B22,Table4[Apr_2026_F]) | P22: =SUMIF(Table4[Workstream],'$ Dashboard'!B22,Table4[Apr_2026_A]) | Q22: =SUMIF(Table4[Workstream],'$ Dashboard'!B22,Table4[May_2026_F]) | R22: =SUMIF(Table4[Workstream],'$ Dashboard'!B22,Table4[May_2026_A]) | S22: =SUMIF(Table4[Workstream],'$ Dashboard'!B22,Table4[Jun_2026_F]) | T22: =SUMIF(Table4[Workstream],'$ Dashboard'!B22,Table4[Jun_2026_A]) | U22: =SUMIF(Table4[Workstream],'$ Dashboard'!B22,Table4[Jul_2026_F]) | V22: =SUMIF(Table4[Workstream],'$ Dashboard'!B22,Table4[Jul_2026_A]) | W22: =SUMIF(Table4[Workstream],'$ Dashboard'!B22,Table4[Aug_2026_F]) | X22: =SUMIF(Table4[Workstream],'$ Dashboard'!B22,Table4[Aug_2026_A]) | Y22: =SUMIF(Table4[Workstream],'$ Dashboard'!B22,Table4[Sep_2026_F]) | Z22: =SUMIF(Table4[Workstream],'$ Dashboard'!B22,Table4[Sep_2026_A]) | AA22: =SUMIF(Table4[Workstream],'$ Dashboard'!B22,Table4[Oct_2026_F]) | AB22: =SUMIF(Table4[Workstream],'$ Dashboard'!B22,Table4[Oct_2026_A]) | AC22: =SUMIF(Table4[Workstream],'$ Dashboard'!B22,Table4[Nov_2026_F]) | AD22: =SUMIF(Table4[Workstream],'$ Dashboard'!B22,Table4[Nov_2026_A]) | AE22: =SUMIF(Table4[Workstream],'$ Dashboard'!B22,Table4[Dec_2026_F]) | AF22: =SUMIF(Table4[Workstream],'$ Dashboard'!B22,Table4[Dec_2026_A])+SUMIF(Table46[Workstream],'$ Dashboard'!B22,Table46[Dec_26_A]) | AH22: =SUM(AW22:BG22)/1000000 | AI22: =SUMIF($AJ$12:$BG$12,"Actual",AJ22:BG22)/1000000 | CD22: =SUM(CE22:DB22)/1000000
D23: =SUM(G23,AH23) | E23: =SUM(H23,AI23) | G23: =SUMIF($I$12:$AF$12,"Plan",I23:AF23)/1000000 | H23: =SUMIF($I$12:$AF$12,"Actual",I23:AF23)/1000000 | I23: =SUMIF(Table410[Workstream],'$ Dashboard'!B23,Table410[Jan_2026_F]) | J23: =SUMIF(Table410[Workstream],'$ Dashboard'!B23,Table410[Jan_2026_A]) | K23: =SUMIF(Table410[Workstream],'$ Dashboard'!B23,Table410[Feb_2026_F]) | L23: =SUMIF(Table410[Workstream],'$ Dashboard'!B23,Table410[Feb_2026_A]) | M23: =SUMIF(Table410[Workstream],'$ Dashboard'!B23,Table410[Mar_2026_F]) | N23: =SUMIF(Table410[Workstream],'$ Dashboard'!B23,Table410[Mar_2026_A]) | O23: =SUMIF(Table410[Workstream],'$ Dashboard'!B23,Table410[Apr_2026_F]) | P23: =SUMIF(Table410[Workstream],'$ Dashboard'!B23,Table410[Apr_2026_A]) | Q23: =SUMIF(Table410[Workstream],'$ Dashboard'!B23,Table410[May_2026_F]) | R23: =SUMIF(Table410[Workstream],'$ Dashboard'!B23,Table410[May_2026_A]) | S23: =SUMIF(Table410[Workstream],'$ Dashboard'!B23,Table410[Jun_2026_F]) | T23: =SUMIF(Table410[Workstream],'$ Dashboard'!B23,Table410[Jun_2026_A]) | U23: =SUMIF(Table410[Workstream],'$ Dashboard'!B23,Table410[Jul_2026_F]) | V23: =SUMIF(Table410[Workstream],'$ Dashboard'!B23,Table410[Jul_2026_A]) | W23: =SUMIF(Table410[Workstream],'$ Dashboard'!B23,Table410[Aug_2026_F]) | X23: =SUMIF(Table410[Workstream],'$ Dashboard'!B23,Table410[Aug_2026_A]) | Y23: =SUMIF(Table410[Workstream],'$ Dashboard'!B23,Table410[Sep_2026_F]) | Z23: =SUMIF(Table410[Workstream],'$ Dashboard'!B23,Table410[Sep_2026_A]) | AA23: =SUMIF(Table410[Workstream],'$ Dashboard'!B23,Table410[Oct_2026_F]) | AB23: =SUMIF(Table410[Workstream],'$ Dashboard'!B23,Table410[Oct_2026_A]) | AC23: =SUMIF(Table410[Workstream],'$ Dashboard'!B23,Table410[Nov_2026_F]) | AD23: =SUMIF(Table410[Workstream],'$ Dashboard'!B23,Table410[Nov_2026_A]) | AE23: =SUMIF(Table410[Workstream],'$ Dashboard'!B23,Table410[Dec_2026_F]) | AF23: =SUMIF(Table410[Workstream],'$ Dashboard'!B23,Table410[Dec_2026_A])+SUMIF(Table46[Workstream],'$ Dashboard'!B23,Table46[Dec_26_A]) | AH23: =SUM(AW23:BG23)/1000000 | AI23: =SUMIF($AJ$12:$BG$12,"Actual",AJ23:BG23)/1000000 | CD23: =SUM(CE23:DB23)/1000000
D24: =SUM(G24,AH24) | E24: =SUM(H24,AI24) | G24: =SUMIF($I$12:$AF$12,"Plan",I24:AF24)/1000000 | H24: =SUMIF($I$12:$AF$12,"Actual",I24:AF24)/1000000 | I24: =SUMIF(Table410[Workstream],'$ Dashboard'!B24,Table410[Jan_2026_F]) | J24: =SUMIF(Table410[Workstream],'$ Dashboard'!B24,Table410[Jan_2026_A]) | K24: =SUMIF(Table410[Workstream],'$ Dashboard'!B24,Table410[Feb_2026_F]) | L24: =SUMIF(Table410[Workstream],'$ Dashboard'!B24,Table410[Feb_2026_A]) | M24: =SUMIF(Table410[Workstream],'$ Dashboard'!B24,Table410[Mar_2026_F]) | N24: =SUMIF(Table410[Workstream],'$ Dashboard'!B24,Table410[Mar_2026_A]) | O24: =SUMIF(Table410[Workstream],'$ Dashboard'!B24,Table410[Apr_2026_F]) | P24: =SUMIF(Table410[Workstream],'$ Dashboard'!B24,Table410[Apr_2026_A]) | Q24: =SUMIF(Table410[Workstream],'$ Dashboard'!B24,Table410[May_2026_F]) | R24: =SUMIF(Table410[Workstream],'$ Dashboard'!B24,Table410[May_2026_A]) | S24: =SUMIF(Table410[Workstream],'$ Dashboard'!B24,Table410[Jun_2026_F]) | T24: =SUMIF(Table410[Workstream],'$ Dashboard'!B24,Table410[Jun_2026_A]) | U24: =SUMIF(Table410[Workstream],'$ Dashboard'!B24,Table410[Jul_2026_F]) | V24: =SUMIF(Table410[Workstream],'$ Dashboard'!B24,Table410[Jul_2026_A]) | W24: =SUMIF(Table410[Workstream],'$ Dashboard'!B24,Table410[Aug_2026_F]) | X24: =SUMIF(Table410[Workstream],'$ Dashboard'!B24,Table410[Aug_2026_A]) | Y24: =SUMIF(Table410[Workstream],'$ Dashboard'!B24,Table410[Sep_2026_F]) | Z24: =SUMIF(Table410[Workstream],'$ Dashboard'!B24,Table410[Sep_2026_A]) | AA24: =SUMIF(Table410[Workstream],'$ Dashboard'!B24,Table410[Oct_2026_F]) | AB24: =SUMIF(Table410[Workstream],'$ Dashboard'!B24,Table410[Oct_2026_A]) | AC24: =SUMIF(Table410[Workstream],'$ Dashboard'!B24,Table410[Nov_2026_F]) | AD24: =SUMIF(Table410[Workstream],'$ Dashboard'!B24,Table410[Nov_2026_A]) | AE24: =SUMIF(Table410[Workstream],'$ Dashboard'!B24,Table410[Dec_2026_F]) | AF24: =SUMIF(Table410[Workstream],'$ Dashboard'!B24,Table410[Dec_2026_A])+SUMIF(Table46[Workstream],'$ Dashboard'!B24,Table46[Dec_26_A]) | AH24: =SUM(AW24:BG24)/1000000 | AI24: =SUMIF($AJ$12:$BG$12,"Actual",AJ24:BG24)/1000000
D25: =SUM(G25,AH25) | E25: =SUM(H25,AI25) | G25: =SUMIF($I$12:$AF$12,"Plan",I25:AF25)/1000000 | H25: =SUMIF($I$12:$AF$12,"Actual",I25:AF25)/1000000 | I25: =SUMIF(Table410[Workstream],'$ Dashboard'!B25,Table410[Jan_2026_F]) | J25: =SUMIF(Table410[Workstream],'$ Dashboard'!B25,Table410[Jan_2026_A]) | K25: =SUMIF(Table410[Workstream],'$ Dashboard'!B25,Table410[Feb_2026_F]) | L25: =SUMIF(Table410[Workstream],'$ Dashboard'!B25,Table410[Feb_2026_A]) | M25: =SUMIF(Table410[Workstream],'$ Dashboard'!B25,Table410[Mar_2026_F]) | N25: =SUMIF(Table410[Workstream],'$ Dashboard'!B25,Table410[Mar_2026_A]) | O25: =SUMIF(Table410[Workstream],'$ Dashboard'!B25,Table410[Apr_2026_F]) | P25: =SUMIF(Table410[Workstream],'$ Dashboard'!B25,Table410[Apr_2026_A]) | Q25: =SUMIF(Table410[Workstream],'$ Dashboard'!B25,Table410[May_2026_F]) | R25: =SUMIF(Table410[Workstream],'$ Dashboard'!B25,Table410[May_2026_A]) | S25: =SUMIF(Table410[Workstream],'$ Dashboard'!B25,Table410[Jun_2026_F]) | T25: =SUMIF(Table410[Workstream],'$ Dashboard'!B25,Table410[Jun_2026_A]) | U25: =SUMIF(Table410[Workstream],'$ Dashboard'!B25,Table410[Jul_2026_F]) | V25: =SUMIF(Table410[Workstream],'$ Dashboard'!B25,Table410[Jul_2026_A]) | W25: =SUMIF(Table410[Workstream],'$ Dashboard'!B25,Table410[Aug_2026_F]) | X25: =SUMIF(Table410[Workstream],'$ Dashboard'!B25,Table410[Aug_2026_A]) | Y25: =SUMIF(Table410[Workstream],'$ Dashboard'!B25,Table410[Sep_2026_F]) | Z25: =SUMIF(Table410[Workstream],'$ Dashboard'!B25,Table410[Sep_2026_A]) | AA25: =SUMIF(Table410[Workstream],'$ Dashboard'!B25,Table410[Oct_2026_F]) | AB25: =SUMIF(Table410[Workstream],'$ Dashboard'!B25,Table410[Oct_2026_A]) | AC25: =SUMIF(Table410[Workstream],'$ Dashboard'!B25,Table410[Nov_2026_F]) | AD25: =SUMIF(Table410[Workstream],'$ Dashboard'!B25,Table410[Nov_2026_A]) | AE25: =SUMIF(Table410[Workstream],'$ Dashboard'!B25,Table410[Dec_2026_F]) | AF25: =SUMIF(Table410[Workstream],'$ Dashboard'!B25,Table410[Dec_2026_A])+SUMIF(Table46[Workstream],'$ Dashboard'!B25,Table46[Dec_26_A]) | AH25: =SUM(AW25:BG25)/1000000 | AI25: =SUMIF($AJ$12:$BG$12,"Actual",AJ25:BG25)/1000000
D26: =SUM(G26,AH26) | E26: =SUM(H26,AI26) | G26: =SUMIF($I$12:$AF$12,"Plan",I26:AF26)/1000000 | H26: =SUMIF($I$12:$AF$12,"Actual",I26:AF26)/1000000 | I26: =SUMIF(Table410[Workstream],'$ Dashboard'!B26,Table410[Jan_2026_F]) | J26: =SUMIF(Table410[Workstream],'$ Dashboard'!B26,Table410[Jan_2026_A]) | K26: =SUMIF(Table410[Workstream],'$ Dashboard'!B26,Table410[Feb_2026_F]) | L26: =SUMIF(Table410[Workstream],'$ Dashboard'!B26,Table410[Feb_2026_A]) | M26: =SUMIF(Table410[Workstream],'$ Dashboard'!B26,Table410[Mar_2026_F]) | N26: =SUMIF(Table410[Workstream],'$ Dashboard'!B26,Table410[Mar_2026_A]) | O26: =SUMIF(Table410[Workstream],'$ Dashboard'!B26,Table410[Apr_2026_F]) | P26: =SUMIF(Table410[Workstream],'$ Dashboard'!B26,Table410[Apr_2026_A]) | Q26: =SUMIF(Table410[Workstream],'$ Dashboard'!B26,Table410[May_2026_F]) | R26: =SUMIF(Table410[Workstream],'$ Dashboard'!B26,Table410[May_2026_A]) | S26: =SUMIF(Table410[Workstream],'$ Dashboard'!B26,Table410[Jun_2026_F]) | T26: =SUMIF(Table410[Workstream],'$ Dashboard'!B26,Table410[Jun_2026_A]) | U26: =SUMIF(Table410[Workstream],'$ Dashboard'!B26,Table410[Jul_2026_F]) | V26: =SUMIF(Table410[Workstream],'$ Dashboard'!B26,Table410[Jul_2026_A]) | W26: =SUMIF(Table410[Workstream],'$ Dashboard'!B26,Table410[Aug_2026_F]) | X26: =SUMIF(Table410[Workstream],'$ Dashboard'!B26,Table410[Aug_2026_A]) | Y26: =SUMIF(Table410[Workstream],'$ Dashboard'!B26,Table410[Sep_2026_F]) | Z26: =SUMIF(Table410[Workstream],'$ Dashboard'!B26,Table410[Sep_2026_A]) | AA26: =SUMIF(Table410[Workstream],'$ Dashboard'!B26,Table410[Oct_2026_F]) | AB26: =SUMIF(Table410[Workstream],'$ Dashboard'!B26,Table410[Oct_2026_A]) | AC26: =SUMIF(Table410[Workstream],'$ Dashboard'!B26,Table410[Nov_2026_F]) | AD26: =SUMIF(Table410[Workstream],'$ Dashboard'!B26,Table410[Nov_2026_A]) | AE26: =SUMIF(Table410[Workstream],'$ Dashboard'!B26,Table410[Dec_2026_F]) | AF26: =SUMIF(Table410[Workstream],'$ Dashboard'!B26,Table410[Dec_2026_A])+SUMIF(Table46[Workstream],'$ Dashboard'!B26,Table46[Dec_26_A]) | AH26: =SUM(AW26:BG26)/1000000 | AI26: =SUMIF($AJ$12:$BG$12,"Actual",AJ26:BG26)/1000000 | CD26: =SUM(CE26:DB26)/1000000
D27: =SUM(G27,AH27) | E27: =SUM(H27,AI27) | G27: =SUMIF($I$12:$AF$12,"Plan",I27:AF27)/1000000 | H27: =SUMIF($I$12:$AF$12,"Actual",I27:AF27)/1000000 | I27: =SUMIF(Table410[Workstream],'$ Dashboard'!B27,Table410[Jan_2026_F]) | J27: =SUMIF(Table410[Workstream],'$ Dashboard'!B27,Table410[Jan_2026_A]) | K27: =SUMIF(Table410[Workstream],'$ Dashboard'!B27,Table410[Feb_2026_F]) | L27: =SUMIF(Table410[Workstream],'$ Dashboard'!B27,Table410[Feb_2026_A]) | M27: =SUMIF(Table410[Workstream],'$ Dashboard'!B27,Table410[Mar_2026_F]) | N27: =SUMIF(Table410[Workstream],'$ Dashboard'!B27,Table410[Mar_2026_A]) | O27: =SUMIF(Table410[Workstream],'$ Dashboard'!B27,Table410[Apr_2026_F]) | P27: =SUMIF(Table410[Workstream],'$ Dashboard'!B27,Table410[Apr_2026_A]) | Q27: =SUMIF(Table410[Workstream],'$ Dashboard'!B27,Table410[May_2026_F]) | R27: =SUMIF(Table410[Workstream],'$ Dashboard'!B27,Table410[May_2026_A]) | S27: =SUMIF(Table410[Workstream],'$ Dashboard'!B27,Table410[Jun_2026_F]) | T27: =SUMIF(Table410[Workstream],'$ Dashboard'!B27,Table410[Jun_2026_A]) | U27: =SUMIF(Table410[Workstream],'$ Dashboard'!B27,Table410[Jul_2026_F]) | V27: =SUMIF(Table410[Workstream],'$ Dashboard'!B27,Table410[Jul_2026_A]) | W27: =SUMIF(Table410[Workstream],'$ Dashboard'!B27,Table410[Aug_2026_F]) | X27: =SUMIF(Table410[Workstream],'$ Dashboard'!B27,Table410[Aug_2026_A]) | Y27: =SUMIF(Table410[Workstream],'$ Dashboard'!B27,Table410[Sep_2026_F]) | Z27: =SUMIF(Table410[Workstream],'$ Dashboard'!B27,Table410[Sep_2026_A]) | AA27: =SUMIF(Table410[Workstream],'$ Dashboard'!B27,Table410[Oct_2026_F]) | AB27: =SUMIF(Table410[Workstream],'$ Dashboard'!B27,Table410[Oct_2026_A]) | AC27: =SUMIF(Table410[Workstream],'$ Dashboard'!B27,Table410[Nov_2026_F]) | AD27: =SUMIF(Table410[Workstream],'$ Dashboard'!B27,Table410[Nov_2026_A]) | AE27: =SUMIF(Table410[Workstream],'$ Dashboard'!B27,Table410[Dec_2026_F]) | AF27: =SUMIF(Table410[Workstream],'$ Dashboard'!B27,Table410[Dec_2026_A])+SUMIF(Table46[Workstream],'$ Dashboard'!B27,Table46[Dec_26_A]) | AH27: =SUM(AW27:BG27)/1000000 | AI27: =SUMIF($AJ$12:$BG$12,"Actual",AJ27:BG27)/1000000 | CD27: =SUM(CE27:DB27)/1000000
D28: =SUM(G28,AH28) | E28: =SUM(H28,AI28) | G28: =SUMIF($I$12:$AF$12,"Plan",I28:AF28)/1000000 | H28: =SUMIF($I$12:$AF$12,"Actual",I28:AF28)/1000000 | I28: =SUMIF(Table410[Workstream],'$ Dashboard'!B28,Table410[Jan_2026_F]) | J28: =SUMIF(Table410[Workstream],'$ Dashboard'!B28,Table410[Jan_2026_A]) | K28: =SUMIF(Table410[Workstream],'$ Dashboard'!B28,Table410[Feb_2026_F]) | L28: =SUMIF(Table410[Workstream],'$ Dashboard'!B28,Table410[Feb_2026_A]) | M28: =SUMIF(Table410[Workstream],'$ Dashboard'!B28,Table410[Mar_2026_F]) | N28: =SUMIF(Table410[Workstream],'$ Dashboard'!B28,Table410[Mar_2026_A]) | O28: =SUMIF(Table410[Workstream],'$ Dashboard'!B28,Table410[Apr_2026_F]) | P28: =SUMIF(Table410[Workstream],'$ Dashboard'!B28,Table410[Apr_2026_A]) | Q28: =SUMIF(Table410[Workstream],'$ Dashboard'!B28,Table410[May_2026_F]) | R28: =SUMIF(Table410[Workstream],'$ Dashboard'!B28,Table410[May_2026_A]) | S28: =SUMIF(Table410[Workstream],'$ Dashboard'!B28,Table410[Jun_2026_F]) | T28: =SUMIF(Table410[Workstream],'$ Dashboard'!B28,Table410[Jun_2026_A]) | U28: =SUMIF(Table410[Workstream],'$ Dashboard'!B28,Table410[Jul_2026_F]) | V28: =SUMIF(Table410[Workstream],'$ Dashboard'!B28,Table410[Jul_2026_A]) | W28: =SUMIF(Table410[Workstream],'$ Dashboard'!B28,Table410[Aug_2026_F]) | X28: =SUMIF(Table410[Workstream],'$ Dashboard'!B28,Table410[Aug_2026_A]) | Y28: =SUMIF(Table410[Workstream],'$ Dashboard'!B28,Table410[Sep_2026_F]) | Z28: =SUMIF(Table410[Workstream],'$ Dashboard'!B28,Table410[Sep_2026_A]) | AA28: =SUMIF(Table410[Workstream],'$ Dashboard'!B28,Table410[Oct_2026_F]) | AB28: =SUMIF(Table410[Workstream],'$ Dashboard'!B28,Table410[Oct_2026_A]) | AC28: =SUMIF(Table410[Workstream],'$ Dashboard'!B28,Table410[Nov_2026_F]) | AD28: =SUMIF(Table410[Workstream],'$ Dashboard'!B28,Table410[Nov_2026_A]) | AE28: =SUMIF(Table410[Workstream],'$ Dashboard'!B28,Table410[Dec_2026_F]) | AF28: =SUMIF(Table410[Workstream],'$ Dashboard'!B28,Table410[Dec_2026_A])+SUMIF(Table46[Workstream],'$ Dashboard'!B28,Table46[Dec_26_A]) | AH28: =SUM(AW28:BG28)/1000000 | AI28: =SUMIF($AJ$12:$BG$12,"Actual",AJ28:BG28)/1000000 | CD28: =SUM(CE28:DB28)/1000000
D29: =SUM(G29,AH29) | E29: =SUM(H29,AI29) | G29: =SUMIF($I$12:$AF$12,"Plan",I29:AF29)/1000000 | H29: =SUMIF($I$12:$AF$12,"Actual",I29:AF29)/1000000 | I29: =SUMIF(Table410[Workstream],'$ Dashboard'!B29,Table410[Jan_2026_F]) | J29: =SUMIF(Table410[Workstream],'$ Dashboard'!B29,Table410[Jan_2026_A]) | K29: =SUMIF(Table410[Workstream],'$ Dashboard'!B29,Table410[Feb_2026_F]) | L29: =SUMIF(Table410[Workstream],'$ Dashboard'!B29,Table410[Feb_2026_A]) | M29: =SUMIF(Table410[Workstream],'$ Dashboard'!B29,Table410[Mar_2026_F]) | N29: =SUMIF(Table410[Workstream],'$ Dashboard'!B29,Table410[Mar_2026_A]) | O29: =SUMIF(Table410[Workstream],'$ Dashboard'!B29,Table410[Apr_2026_F]) | P29: =SUMIF(Table410[Workstream],'$ Dashboard'!B29,Table410[Apr_2026_A]) | Q29: =SUMIF(Table410[Workstream],'$ Dashboard'!B29,Table410[May_2026_F]) | R29: =SUMIF(Table410[Workstream],'$ Dashboard'!B29,Table410[May_2026_A]) | S29: =SUMIF(Table410[Workstream],'$ Dashboard'!B29,Table410[Jun_2026_F]) | T29: =SUMIF(Table410[Workstream],'$ Dashboard'!B29,Table410[Jun_2026_A]) | U29: =SUMIF(Table410[Workstream],'$ Dashboard'!B29,Table410[Jul_2026_F]) | V29: =SUMIF(Table410[Workstream],'$ Dashboard'!B29,Table410[Jul_2026_A]) | W29: =SUMIF(Table410[Workstream],'$ Dashboard'!B29,Table410[Aug_2026_F]) | X29: =SUMIF(Table410[Workstream],'$ Dashboard'!B29,Table410[Aug_2026_A]) | Y29: =SUMIF(Table410[Workstream],'$ Dashboard'!B29,Table410[Sep_2026_F]) | Z29: =SUMIF(Table410[Workstream],'$ Dashboard'!B29,Table410[Sep_2026_A]) | AA29: =SUMIF(Table410[Workstream],'$ Dashboard'!B29,Table410[Oct_2026_F]) | AB29: =SUMIF(Table410[Workstream],'$ Dashboard'!B29,Table410[Oct_2026_A]) | AC29: =SUMIF(Table410[Workstream],'$ Dashboard'!B29,Table410[Nov_2026_F]) | AD29: =SUMIF(Table410[Workstream],'$ Dashboard'!B29,Table410[Nov_2026_A]) | AE29: =SUMIF(Table410[Workstream],'$ Dashboard'!B29,Table410[Dec_2026_F]) | AF29: =SUMIF(Table410[Workstream],'$ Dashboard'!B29,Table410[Dec_2026_A])+SUMIF(Table46[Workstream],'$ Dashboard'!B29,Table46[Dec_26_A]) | AH29: =SUM(AW29:BG29)/1000000 | AI29: =SUMIF($AJ$12:$BG$12,"Actual",AJ29:BG29)/1000000 | CD29: =SUM(CE29:DB29)/1000000
B30: Total | D30: =SUM(D13:D29) | E30: =SUM(E13:E29) | G30: =SUM(G13:G29) | H30: =SUM(H13:H29) | I30: =SUM(I13:I29) | J30: =SUM(J13:J29) | K30: =SUM(K13:K29) | L30: =SUM(L13:L29) | M30: =SUM(M13:M29) | N30: =SUM(N13:N29) | ... AF30: =SUM(AF13:AF29) | AH30: =SUM(AH13:AH29) | AI30: =SUM(AI13:AI29) | AJ30: =SUM(AJ13:AJ29) | AK30: =SUM(AK13:AK29) | AL30: =SUM(AL13:AL29) | AM30: =SUM(AM13:AM29) | AN30: =SUM(AN13:AN29) | AO30: =SUM(AO13:AO29) | ... BG30: =SUM(BG13:BG29) | CD30: =SUM(CD13:CD29) | CE30: =SUM(CE13:CE29) | CF30: =SUM(CF13:CF29) | CG30: =SUM(CG13:CG29) | CH30: =SUM(CH13:CH29) | CI30: =SUM(CI13:CI29) | CJ30: =SUM(CJ13:CJ29) | CK30: =SUM(CK13:CK29) | ... DB30: =SUM(DB13:DB29)
AK31: =IFERROR(AK30/AJ30,0) | AM31: =IFERROR(AM30/AL30,0) | AO31: =IFERROR(AO30/AN30,0) | AQ31: =IFERROR(AQ30/AP30,0) | AS31: =IFERROR(AS30/AR30,0) | AU31: =IFERROR(AU30/AT30,0) | AW31: =IFERROR(AW30/AV30,0) | AY31: =IFERROR(AY30/AX30,0) | BA31: =IFERROR(BA30/AZ30,0) | BC31: =IFERROR(BC30/BB30,0) | BE31: =IFERROR(BE30/BD30,0) | BG31: =IFERROR(BG30/BF30,0)
D35: [2026 - 2027] | G35: [2026] | AH35: [2027]
B36: Business Resource cost by WS/PH | C36: Business/IT | D36: Program LE | E36: Program YTD Actual | G36: LE | H36: Actual | I36: 46023 | K36: 46054 | M36: 46082 | O36: 46113 | Q36: 46143 | S36: 46174 | U36: 46204 | W36: 46235 | Y36: 46266 | AA36: 46296 | AC36: 46327 | AE36: 46357 | AH36: LE | AI36: Actual | AJ36: 46388 | AL36: 46419 | AN36: 46447 | AP36: 46478 | AR36: 46508 | AT36: 46539 | AV36: 46569 | AX36: 46600 | AZ36: 46631 | BB36: 46661 | BD36: 46692 | BF36: 46722 | CD36: GIP | CE36: 46023 | CF36: 46054 | CG36: 46082 | CH36: 46113 | CI36: 46143 | CJ36: 46174 | CK36: 46204 | CL36: 46235 | CM36: 46266 | CN36: 46296 | CO36: 46327 | CP36: 46357 | CQ36: 46388 | CR36: 46419 | CS36: 46447 | CT36: 46478 | CU36: 46508 | CV36: 46539 | CW36: 46569 | CX36: 46600 | CY36: 46631 | CZ36: 46661 | DA36: 46692 | DB36: 46722
I37: Plan | J37: Actual | K37: Plan | L37: Actual | M37: Plan | N37: Actual | O37: Plan | P37: Actual | Q37: Plan | R37: Actual | S37: Plan | T37: Actual | U37: Plan | V37: Actual | W37: Plan | X37: Actual | Y37: Plan | Z37: Actual | AA37: Plan | AB37: Actual | AC37: Plan | AD37: Actual | AE37: Plan | AF37: Actual | AJ37: Plan | AK37: =IF(AJ36<=$B$5,"Actual","") | AL37: Plan | AM37: =IF(AL36<=$B$5,"Actual","") | AN37: Plan | AO37: =IF(AN36<=$B$5,"Actual","") | AP37: Plan | AQ37: =IF(AP36<=$B$5,"Actual","") | AR37: Plan | AS37: =IF(AR36<=$B$5,"Actual","") | AT37: Plan | AU37: =IF(AT36<=$B$5,"Actual","") | AV37: Plan | AW37: =IF(AV36<=$B$5,"Actual","") | AX37: Plan | AY37: =IF(AX36<=$B$5,"Actual","") | AZ37: Plan | BA37: =IF(AZ36<=$B$5,"Actual","") | BB37: Plan | BC37: =IF(BB36<=$B$5,"Actual","") | BD37: Plan | BE37: =IF(BD36<=$B$5,"Actual","") | BF37: Plan | BG37: =IF(BF36<=$B$5,"Actual","")
B38: Program Management | C38: Business | D38: =SUM(G38,AH38) | E38: =SUM(H38,AI38) | G38: =SUMIF($I$12:$AF$12,"Plan",I38:AF38)/1000000 | H38: =SUMIF($I$12:$AF$12,"Actual",I38:AF38)/1000000 | I38: =SUMIF(Table410[Workstream],'$ Dashboard'!B38,Table410[Jan_2026_F]) | J38: =SUMIF(Table410[Workstream],'$ Dashboard'!B38,Table410[Jan_2026_A]) | K38: =SUMIF(Table410[Workstream],'$ Dashboard'!B38,Table410[Feb_2026_F]) | L38: =SUMIF(Table410[Workstream],'$ Dashboard'!B38,Table410[Feb_2026_A]) | M38: =SUMIF(Table410[Workstream],'$ Dashboard'!B38,Table410[Mar_2026_F]) | N38: =SUMIF(Table410[Workstream],'$ Dashboard'!B38,Table410[Mar_2026_A]) | O38: =SUMIF(Table410[Workstream],'$ Dashboard'!B38,Table410[Apr_2026_F]) | P38: =SUMIF(Table410[Workstream],'$ Dashboard'!B38,Table410[Apr_2026_A]) | Q38: =SUMIF(Table410[Workstream],'$ Dashboard'!B38,Table410[May_2026_F]) | R38: =SUMIF(Table410[Workstream],'$ Dashboard'!B38,Table410[May_2026_A]) | S38: =SUMIF(Table410[Workstream],'$ Dashboard'!B38,Table410[Jun_2026_F]) | T38: =SUMIF(Table410[Workstream],'$ Dashboard'!B38,Table410[Jun_2026_A]) | U38: =SUMIF(Table410[Workstream],'$ Dashboard'!B38,Table410[Jul_2026_F]) | V38: =SUMIF(Table410[Workstream],'$ Dashboard'!B38,Table410[Jul_2026_A]) | W38: =SUMIF(Table410[Workstream],'$ Dashboard'!B38,Table410[Aug_2026_F]) | X38: =SUMIF(Table410[Workstream],'$ Dashboard'!B38,Table410[Aug_2026_A]) | Y38: =SUMIF(Table410[Workstream],'$ Dashboard'!B38,Table410[Sep_2026_F]) | Z38: =SUMIF(Table410[Workstream],'$ Dashboard'!B38,Table410[Sep_2026_A]) | AA38: =SUMIF(Table410[Workstream],'$ Dashboard'!B38,Table410[Oct_2026_F]) | AB38: =SUMIF(Table410[Workstream],'$ Dashboard'!B38,Table410[Oct_2026_A]) | AC38: =SUMIF(Table410[Workstream],'$ Dashboard'!B38,Table410[Nov_2026_F]) | AD38: =SUMIF(Table410[Workstream],'$ Dashboard'!B38,Table410[Nov_2026_A]) | AE38: =SUMIF(Table410[Workstream],'$ Dashboard'!B38,Table410[Dec_2026_F]) | AF38: =SUMIF(Table410[Workstream],'$ Dashboard'!B38,Table410[Dec_2026_A])+SUMIF(Table46[Workstream],'$ Dashboard'!B38,Table46[Dec_26_A]) | AH38: =SUM(AW38:BG38)/1000000 | AI38: =SUMIF($AJ$12:$BG$12,"Actual",AJ38:BG38)/1000000 | CD38: =SUM(CE38:DB38)/1000000
B39: Prosmar Crude | C39: Business | D39: =SUM(G39,AH39) | E39: =SUM(H39,AI39) | G39: =SUMIF($I$12:$AF$12,"Plan",I39:AF39)/1000000 | H39: =SUMIF($I$12:$AF$12,"Actual",I39:AF39)/1000000 | I39: =SUMIF(Table410[Workstream],'$ Dashboard'!B39,Table410[Jan_2026_F]) | J39: =SUMIF(Table410[Workstream],'$ Dashboard'!B39,Table410[Jan_2026_A]) | K39: =SUMIF(Table410[Workstream],'$ Dashboard'!B39,Table410[Feb_2026_F]) | L39: =SUMIF(Table410[Workstream],'$ Dashboard'!B39,Table410[Feb_2026_A]) | M39: =SUMIF(Table410[Workstream],'$ Dashboard'!B39,Table410[Mar_2026_F]) | N39: =SUMIF(Table410[Workstream],'$ Dashboard'!B39,Table410[Mar_2026_A]) | O39: =SUMIF(Table410[Workstream],'$ Dashboard'!B39,Table410[Apr_2026_F]) | P39: =SUMIF(Table410[Workstream],'$ Dashboard'!B39,Table410[Apr_2026_A]) | Q39: =SUMIF(Table410[Workstream],'$ Dashboard'!B39,Table410[May_2026_F]) | R39: =SUMIF(Table410[Workstream],'$ Dashboard'!B39,Table410[May_2026_A]) | S39: =SUMIF(Table410[Workstream],'$ Dashboard'!B39,Table410[Jun_2026_F]) | T39: =SUMIF(Table410[Workstream],'$ Dashboard'!B39,Table410[Jun_2026_A]) | U39: =SUMIF(Table410[Workstream],'$ Dashboard'!B39,Table410[Jul_2026_F]) | V39: =SUMIF(Table410[Workstream],'$ Dashboard'!B39,Table410[Jul_2026_A]) | W39: =SUMIF(Table410[Workstream],'$ Dashboard'!B39,Table410[Aug_2026_F]) | X39: =SUMIF(Table410[Workstream],'$ Dashboard'!B39,Table410[Aug_2026_A]) | Y39: =SUMIF(Table410[Workstream],'$ Dashboard'!B39,Table410[Sep_2026_F]) | Z39: =SUMIF(Table410[Workstream],'$ Dashboard'!B39,Table410[Sep_2026_A]) | AA39: =SUMIF(Table410[Workstream],'$ Dashboard'!B39,Table410[Oct_2026_F]) | AB39: =SUMIF(Table410[Workstream],'$ Dashboard'!B39,Table410[Oct_2026_A]) | AC39: =SUMIF(Table410[Workstream],'$ Dashboard'!B39,Table410[Nov_2026_F]) | AD39: =SUMIF(Table410[Workstream],'$ Dashboard'!B39,Table410[Nov_2026_A]) | AE39: =SUMIF(Table410[Workstream],'$ Dashboard'!B39,Table410[Dec_2026_F]) | AF39: =SUMIF(Table410[Workstream],'$ Dashboard'!B39,Table410[Dec_2026_A])+SUMIF(Table46[Workstream],'$ Dashboard'!B39,Table46[Dec_26_A]) | AH39: =SUM(AW39:BG39)/1000000 | AI39: =SUMIF($AJ$12:$BG$12,"Actual",AJ39:BG39)/1000000
B40: Prosmar Products | C40: Business | D40: =SUM(G40,AH40) | E40: =SUM(H40,AI40) | G40: =SUMIF($I$12:$AF$12,"Plan",I40:AF40)/1000000 | H40: =SUMIF($I$12:$AF$12,"Actual",I40:AF40)/1000000 | I40: =SUMIF(Table410[Workstream],'$ Dashboard'!B40,Table410[Jan_2026_F]) | J40: =SUMIF(Table410[Workstream],'$ Dashboard'!B40,Table410[Jan_2026_A]) | K40: =SUMIF(Table410[Workstream],'$ Dashboard'!B40,Table410[Feb_2026_F]) | L40: =SUMIF(Table410[Workstream],'$ Dashboard'!B40,Table410[Feb_2026_A]) | M40: =SUMIF(Table410[Workstream],'$ Dashboard'!B40,Table410[Mar_2026_F]) | N40: =SUMIF(Table410[Workstream],'$ Dashboard'!B40,Table410[Mar_2026_A]) | O40: =SUMIF(Table410[Workstream],'$ Dashboard'!B40,Table410[Apr_2026_F]) | P40: =SUMIF(Table410[Workstream],'$ Dashboard'!B40,Table410[Apr_2026_A]) | Q40: =SUMIF(Table410[Workstream],'$ Dashboard'!B40,Table410[May_2026_F]) | R40: =SUMIF(Table410[Workstream],'$ Dashboard'!B40,Table410[May_2026_A]) | S40: =SUMIF(Table410[Workstream],'$ Dashboard'!B40,Table410[Jun_2026_F]) | T40: =SUMIF(Table410[Workstream],'$ Dashboard'!B40,Table410[Jun_2026_A]) | U40: =SUMIF(Table410[Workstream],'$ Dashboard'!B40,Table410[Jul_2026_F]) | V40: =SUMIF(Table410[Workstream],'$ Dashboard'!B40,Table410[Jul_2026_A]) | W40: =SUMIF(Table410[Workstream],'$ Dashboard'!B40,Table410[Aug_2026_F]) | X40: =SUMIF(Table410[Workstream],'$ Dashboard'!B40,Table410[Aug_2026_A]) | Y40: =SUMIF(Table410[Workstream],'$ Dashboard'!B40,Table410[Sep_2026_F]) | Z40: =SUMIF(Table410[Workstream],'$ Dashboard'!B40,Table410[Sep_2026_A]) | AA40: =SUMIF(Table410[Workstream],'$ Dashboard'!B40,Table410[Oct_2026_F]) | AB40: =SUMIF(Table410[Workstream],'$ Dashboard'!B40,Table410[Oct_2026_A]) | AC40: =SUMIF(Table410[Workstream],'$ Dashboard'!B40,Table410[Nov_2026_F]) | AD40: =SUMIF(Table410[Workstream],'$ Dashboard'!B40,Table410[Nov_2026_A]) | AE40: =SUMIF(Table410[Workstream],'$ Dashboard'!B40,Table410[Dec_2026_F]) | AF40: =SUMIF(Table410[Workstream],'$ Dashboard'!B40,Table410[Dec_2026_A])+SUMIF(Table46[Workstream],'$ Dashboard'!B40,Table46[Dec_26_A]) | AH40: =SUM(AW40:BG40)/1000000 | AI40: =SUMIF($AJ$12:$BG$12,"Actual",AJ40:BG40)/1000000
B41: VPD | C41: Business | D41: =SUM(G41,AH41) | E41: =SUM(H41,AI41) | G41: =SUMIF($I$12:$AF$12,"Plan",I41:AF41)/1000000 | H41: =SUMIF($I$12:$AF$12,"Actual",I41:AF41)/1000000 | I41: =SUMIF(Table410[Workstream],'$ Dashboard'!B41,Table410[Jan_2026_F]) | J41: =SUMIF(Table410[Workstream],'$ Dashboard'!B41,Table410[Jan_2026_A]) | K41: =SUMIF(Table410[Workstream],'$ Dashboard'!B41,Table410[Feb_2026_F]) | L41: =SUMIF(Table410[Workstream],'$ Dashboard'!B41,Table410[Feb_2026_A]) | M41: =SUMIF(Table410[Workstream],'$ Dashboard'!B41,Table410[Mar_2026_F]) | N41: =SUMIF(Table410[Workstream],'$ Dashboard'!B41,Table410[Mar_2026_A]) | O41: =SUMIF(Table410[Workstream],'$ Dashboard'!B41,Table410[Apr_2026_F]) | P41: =SUMIF(Table410[Workstream],'$ Dashboard'!B41,Table410[Apr_2026_A]) | Q41: =SUMIF(Table410[Workstream],'$ Dashboard'!B41,Table410[May_2026_F]) | R41: =SUMIF(Table410[Workstream],'$ Dashboard'!B41,Table410[May_2026_A]) | S41: =SUMIF(Table410[Workstream],'$ Dashboard'!B41,Table410[Jun_2026_F]) | T41: =SUMIF(Table410[Workstream],'$ Dashboard'!B41,Table410[Jun_2026_A]) | U41: =SUMIF(Table410[Workstream],'$ Dashboard'!B41,Table410[Jul_2026_F]) | V41: =SUMIF(Table410[Workstream],'$ Dashboard'!B41,Table410[Jul_2026_A]) | W41: =SUMIF(Table410[Workstream],'$ Dashboard'!B41,Table410[Aug_2026_F]) | X41: =SUMIF(Table410[Workstream],'$ Dashboard'!B41,Table410[Aug_2026_A]) | Y41: =SUMIF(Table410[Workstream],'$ Dashboard'!B41,Table410[Sep_2026_F]) | Z41: =SUMIF(Table410[Workstream],'$ Dashboard'!B41,Table410[Sep_2026_A]) | AA41: =SUMIF(Table410[Workstream],'$ Dashboard'!B41,Table410[Oct_2026_F]) | AB41: =SUMIF(Table410[Workstream],'$ Dashboard'!B41,Table410[Oct_2026_A]) | AC41: =SUMIF(Table410[Workstream],'$ Dashboard'!B41,Table410[Nov_2026_F]) | AD41: =SUMIF(Table410[Workstream],'$ Dashboard'!B41,Table410[Nov_2026_A]) | AE41: =SUMIF(Table410[Workstream],'$ Dashboard'!B41,Table410[Dec_2026_F]) | AF41: =SUMIF(Table410[Workstream],'$ Dashboard'!B41,Table410[Dec_2026_A])+SUMIF(Table46[Workstream],'$ Dashboard'!B41,Table46[Dec_26_A]) | AH41: =SUM(AW41:BG41)/1000000 | AI41: =SUMIF($AJ$12:$BG$12,"Actual",AJ41:BG41)/1000000 | CD41: =SUM(CE41:DB41)/1000000
B42: GATOR | C42: Business | D42: =SUM(G42,AH42) | E42: =SUM(H42,AI42) | G42: =SUMIF($I$12:$AF$12,"Plan",I42:AF42)/1000000 | H42: =SUMIF($I$12:$AF$12,"Actual",I42:AF42)/1000000 | I42: =SUMIF(Table410[Workstream],'$ Dashboard'!B42,Table410[Jan_2026_F]) | J42: =SUMIF(Table410[Workstream],'$ Dashboard'!B42,Table410[Jan_2026_A]) | K42: =SUMIF(Table410[Workstream],'$ Dashboard'!B42,Table410[Feb_2026_F]) | L42: =SUMIF(Table410[Workstream],'$ Dashboard'!B42,Table410[Feb_2026_A]) | M42: =SUMIF(Table410[Workstream],'$ Dashboard'!B42,Table410[Mar_2026_F]) | N42: =SUMIF(Table410[Workstream],'$ Dashboard'!B42,Table410[Mar_2026_A]) | O42: =SUMIF(Table410[Workstream],'$ Dashboard'!B42,Table410[Apr_2026_F]) | P42: =SUMIF(Table410[Workstream],'$ Dashboard'!B42,Table410[Apr_2026_A]) | Q42: =SUMIF(Table410[Workstream],'$ Dashboard'!B42,Table410[May_2026_F]) | R42: =SUMIF(Table410[Workstream],'$ Dashboard'!B42,Table410[May_2026_A]) | S42: =SUMIF(Table410[Workstream],'$ Dashboard'!B42,Table410[Jun_2026_F]) | T42: =SUMIF(Table410[Workstream],'$ Dashboard'!B42,Table410[Jun_2026_A]) | U42: =SUMIF(Table410[Workstream],'$ Dashboard'!B42,Table410[Jul_2026_F]) | V42: =SUMIF(Table410[Workstream],'$ Dashboard'!B42,Table410[Jul_2026_A]) | W42: =SUMIF(Table410[Workstream],'$ Dashboard'!B42,Table410[Aug_2026_F]) | X42: =SUMIF(Table410[Workstream],'$ Dashboard'!B42,Table410[Aug_2026_A]) | Y42: =SUMIF(Table410[Workstream],'$ Dashboard'!B42,Table410[Sep_2026_F]) | Z42: =SUMIF(Table410[Workstream],'$ Dashboard'!B42,Table410[Sep_2026_A]) | AA42: =SUMIF(Table410[Workstream],'$ Dashboard'!B42,Table410[Oct_2026_F]) | AB42: =SUMIF(Table410[Workstream],'$ Dashboard'!B42,Table410[Oct_2026_A]) | AC42: =SUMIF(Table410[Workstream],'$ Dashboard'!B42,Table410[Nov_2026_F]) | AD42: =SUMIF(Table410[Workstream],'$ Dashboard'!B42,Table410[Nov_2026_A]) | AE42: =SUMIF(Table410[Workstream],'$ Dashboard'!B42,Table410[Dec_2026_F]) | AF42: =SUMIF(Table410[Workstream],'$ Dashboard'!B42,Table410[Dec_2026_A])+SUMIF(Table46[Workstream],'$ Dashboard'!B42,Table46[Dec_26_A]) | AH42: =SUM(AW42:BG42)/1000000 | AI42: =SUMIF($AJ$12:$BG$12,"Actual",AJ42:BG42)/1000000 | CD42: =SUM(CE42:DB42)/1000000
B43: USDF | C43: Business | D43: =SUM(G43,AH43) | E43: =SUM(H43,AI43) | G43: =SUMIF($I$12:$AF$12,"Plan",I43:AF43)/1000000 | H43: =SUMIF($I$12:$AF$12,"Actual",I43:AF43)/1000000 | I43: =SUMIF(Table410[Workstream],'$ Dashboard'!B43,Table410[Jan_2026_F]) | J43: =SUMIF(Table410[Workstream],'$ Dashboard'!B43,Table410[Jan_2026_A]) | K43: =SUMIF(Table410[Workstream],'$ Dashboard'!B43,Table410[Feb_2026_F]) | L43: =SUMIF(Table410[Workstream],'$ Dashboard'!B43,Table410[Feb_2026_A]) | M43: =SUMIF(Table410[Workstream],'$ Dashboard'!B43,Table410[Mar_2026_F]) | N43: =SUMIF(Table410[Workstream],'$ Dashboard'!B43,Table410[Mar_2026_A]) | O43: =SUMIF(Table410[Workstream],'$ Dashboard'!B43,Table410[Apr_2026_F]) | P43: =SUMIF(Table410[Workstream],'$ Dashboard'!B43,Table410[Apr_2026_A]) | Q43: =SUMIF(Table410[Workstream],'$ Dashboard'!B43,Table410[May_2026_F]) | R43: =SUMIF(Table410[Workstream],'$ Dashboard'!B43,Table410[May_2026_A]) | S43: =SUMIF(Table410[Workstream],'$ Dashboard'!B43,Table410[Jun_2026_F]) | T43: =SUMIF(Table410[Workstream],'$ Dashboard'!B43,Table410[Jun_2026_A]) | U43: =SUMIF(Table410[Workstream],'$ Dashboard'!B43,Table410[Jul_2026_F]) | V43: =SUMIF(Table410[Workstream],'$ Dashboard'!B43,Table410[Jul_2026_A]) | W43: =SUMIF(Table410[Workstream],'$ Dashboard'!B43,Table410[Aug_2026_F]) | X43: =SUMIF(Table410[Workstream],'$ Dashboard'!B43,Table410[Aug_2026_A]) | Y43: =SUMIF(Table410[Workstream],'$ Dashboard'!B43,Table410[Sep_2026_F]) | Z43: =SUMIF(Table410[Workstream],'$ Dashboard'!B43,Table410[Sep_2026_A]) | AA43: =SUMIF(Table410[Workstream],'$ Dashboard'!B43,Table410[Oct_2026_F]) | AB43: =SUMIF(Table410[Workstream],'$ Dashboard'!B43,Table410[Oct_2026_A]) | AC43: =SUMIF(Table410[Workstream],'$ Dashboard'!B43,Table410[Nov_2026_F]) | AD43: =SUMIF(Table410[Workstream],'$ Dashboard'!B43,Table410[Nov_2026_A]) | AE43: =SUMIF(Table410[Workstream],'$ Dashboard'!B43,Table410[Dec_2026_F]) | AF43: =SUMIF(Table410[Workstream],'$ Dashboard'!B43,Table410[Dec_2026_A])+SUMIF(Table46[Workstream],'$ Dashboard'!B43,Table46[Dec_26_A]) | AH43: =SUM(AW43:BG43)/1000000 | AI43: =SUMIF($AJ$12:$BG$12,"Actual",AJ43:BG43)/1000000 | CD43: =SUM(CE43:DB43)/1000000
B44: JIGSAW & PDS Process work | C44: Business | D44: =SUM(G44,AH44) | E44: =SUM(H44,AI44) | G44: =SUMIF($I$12:$AF$12,"Plan",I44:AF44)/1000000 | H44: =SUMIF($I$12:$AF$12,"Actual",I44:AF44)/1000000 | I44: =SUMIF(Table410[Workstream],'$ Dashboard'!B44,Table410[Jan_2026_F]) | J44: =SUMIF(Table410[Workstream],'$ Dashboard'!B44,Table410[Jan_2026_A]) | K44: =SUMIF(Table410[Workstream],'$ Dashboard'!B44,Table410[Feb_2026_F]) | L44: =SUMIF(Table410[Workstream],'$ Dashboard'!B44,Table410[Feb_2026_A]) | M44: =SUMIF(Table410[Workstream],'$ Dashboard'!B44,Table410[Mar_2026_F]) | N44: =SUMIF(Table410[Workstream],'$ Dashboard'!B44,Table410[Mar_2026_A]) | O44: =SUMIF(Table410[Workstream],'$ Dashboard'!B44,Table410[Apr_2026_F]) | P44: =SUMIF(Table410[Workstream],'$ Dashboard'!B44,Table410[Apr_2026_A]) | Q44: =SUMIF(Table410[Workstream],'$ Dashboard'!B44,Table410[May_2026_F]) | R44: =SUMIF(Table410[Workstream],'$ Dashboard'!B44,Table410[May_2026_A]) | S44: =SUMIF(Table410[Workstream],'$ Dashboard'!B44,Table410[Jun_2026_F]) | T44: =SUMIF(Table410[Workstream],'$ Dashboard'!B44,Table410[Jun_2026_A]) | U44: =SUMIF(Table410[Workstream],'$ Dashboard'!B44,Table410[Jul_2026_F]) | V44: =SUMIF(Table410[Workstream],'$ Dashboard'!B44,Table410[Jul_2026_A]) | W44: =SUMIF(Table410[Workstream],'$ Dashboard'!B44,Table410[Aug_2026_F]) | X44: =SUMIF(Table410[Workstream],'$ Dashboard'!B44,Table410[Aug_2026_A]) | Y44: =SUMIF(Table410[Workstream],'$ Dashboard'!B44,Table410[Sep_2026_F]) | Z44: =SUMIF(Table410[Workstream],'$ Dashboard'!B44,Table410[Sep_2026_A]) | AA44: =SUMIF(Table410[Workstream],'$ Dashboard'!B44,Table410[Oct_2026_F]) | AB44: =SUMIF(Table410[Workstream],'$ Dashboard'!B44,Table410[Oct_2026_A]) | AC44: =SUMIF(Table410[Workstream],'$ Dashboard'!B44,Table410[Nov_2026_F]) | AD44: =SUMIF(Table410[Workstream],'$ Dashboard'!B44,Table410[Nov_2026_A]) | AE44: =SUMIF(Table410[Workstream],'$ Dashboard'!B44,Table410[Dec_2026_F]) | AF44: =SUMIF(Table410[Workstream],'$ Dashboard'!B44,Table410[Dec_2026_A])+SUMIF(Table46[Workstream],'$ Dashboard'!B44,Table46[Dec_26_A]) | AH44: =SUM(AW44:BG44)/1000000 | AI44: =SUMIF($AJ$12:$BG$12,"Actual",AJ44:BG44)/1000000 | CD44: =SUM(CE44:DB44)/1000000
